Workbook

Sheet Tabelle1
A1: Template for Sample Info for FLA Service
A3: Just enter your sample info in the 96well plate table below. Please do not fill 'Sample plate overview' directly; it is filled automatically.
A4: Sample name must not exceed 25 characters and not include special characters or blank spaces.
A6: The filling direction is illustrated in the image to the right (start: well A1 to H1, A2 to H2 etc.).
A7: Conveniently print an overview of your plate via the "sample plate overview" excel sheet tab.
A9: If you sent more than one plate just copy this sheet and give the respective plate names in line 13.
A11: Please fill in the weblogin and Name - this helps to process your samples much smoother
A12: Weblogin | B12: mosler@mpiib-berlin.mpg.de | F12: Customer name | G12: Karolina Mosler
A14: Plate 1
B15: mandatory | C15: mandatory | D15: mandatory | E15: optional | F15: optional | G15: optional
A16: Well | B16: Sample name | C16: Fluorescent dyes used | D16: Expected fragment lengths | E16: Size standard used | F16: DNA / PCR product concentration [ng/µL] | G16: Remarks
A17: A1 | B17: 3D7_10K | C17: FAM | D17: FAM 286
A18: B1 | B18: Dd2_10K | C18: FAM | D18: FAM 286
A19: C1 | B19: NTC | C19: FAM | D19: FAM 286
A20: D1 | B20: 8010683 | C20: FAM | D20: FAM 286
A21: E1 | B21: 8034059 | C21: FAM | D21: FAM 286
A22: F1 | B22: 8012421 | C22: FAM | D22: FAM 286
A23: G1 | B23: 8032055 | C23: FAM | D23: FAM 286
A24: H1 | B24: 5053837 | C24: FAM | D24: FAM 286
A25: A2 | B25: 8022279 | C25: FAM | D25: FAM 286
A26: B2 | B26: 1012556 | C26: FAM | D26: FAM 286
A27: C2 | B27: 1046680 | C27: FAM | D27: FAM 286
A28: D2 | B28: 8034050 | C28: FAM | D28: FAM 286
A29: E2 | B29: 8023299 | C29: FAM | D29: FAM 286
A30: F2 | B30: 8034017 | C30: FAM | D30: FAM 286
A31: G2 | B31: 8013498 | C31: FAM | D31: FAM 286
... A109: E12 | B109: 8023348 | C109: FAM | D109: FAM 286
A110: F12 | B110: 3D7_1K | C110: FAM | D110: FAM 286
A111: G12 | B111: Dd2_1K | C111: FAM | D111: FAM 286
A112: H12 | B112: NTC | C112: FAM | D112: FAM 286
A113: Plate 2 | E113: optional | F113: optional | G113: optional
A114: Well | E114: Size standard used | F114: DNA / PCR product concentration [ng/µL] | G114: Remarks
A115: A1
A116: B1
A117: C1
A118: D1
A119: E1
A120: F1
A121: G1
A122: H1
...

Sheet !Sample Plate Overview
A1: Sample Plate Overview | M1: C-APGFOR
A4: Date | C4: dd/mm/yyyy
A8: Sample Plate Overview | F8: Plate 1
B10: 1 | C10: 2 | D10: 3 | E10: 4 | F10: 5 | G10: 6 | H10: 7 | I10: 8 | J10: 9 | K10: 10 | L10: 11 | M10: 12
A11: A | B11: =Tabelle1!$B17 -> 3D7_10K | C11: =Tabelle1!$B25 -> 8022279 | D11: =Tabelle1!$B33 -> 8034025 | E11: =Tabelle1!$B41 -> 8021039 | F11: =Tabelle1!$B49 -> 1046689 | G11: =Tabelle1!$B57 -> 8034024 | H11: =Tabelle1!$B65 -> 8033344 | I11: =Tabelle1!$B73 -> 8031772 | J11: =Tabelle1!$B81 -> 8034048 | K11: =Tabelle1!$B89 -> 8032330 | L11: =Tabelle1!$B97 -> 8034003 | M11: =Tabelle1!$B105 -> 8023349
A12: B | B12: =Tabelle1!B18 -> Dd2_10K | C12: =Tabelle1!$B26 -> 1012556 | D12: =Tabelle1!$B34 -> 8034028 | E12: =Tabelle1!$B42 -> 8034002 | F12: =Tabelle1!$B50 -> 8033415 | G12: =Tabelle1!$B58 -> 8032579 | H12: =Tabelle1!$B66 -> 8033369 | I12: =Tabelle1!$B74 -> 8032032 | J12: =Tabelle1!$B82 -> 8034052 | K12: =Tabelle1!$B90 -> 8032277 | L12: =Tabelle1!$B98 -> 8032526 | M12: =Tabelle1!$B106 -> 8023337
A13: C | B13: =Tabelle1!B19 -> NTC | C13: =Tabelle1!$B27 -> 1046680 | D13: =Tabelle1!$B35 -> 8023430 | E13: =Tabelle1!$B43 -> 8032343 | F13: =Tabelle1!$B51 -> 1046678 | G13: =Tabelle1!$B59 -> 8032589 | H13: =Tabelle1!$B67 -> 8033385 | I13: =Tabelle1!$B75 -> 8032013 | J13: =Tabelle1!$B83 -> 8034049 | K13: =Tabelle1!$B91 -> 8034006 | L13: =Tabelle1!$B99 -> 8032558 | M13: =Tabelle1!$B107 -> 8023345
A14: D | B14: =Tabelle1!B20 -> 8010683 | C14: =Tabelle1!$B28 -> 8034050 | D14: =Tabelle1!$B36 -> 8021935 | E14: =Tabelle1!$B44 -> 8021930 | F14: =Tabelle1!$B52 -> 1046675 | G14: =Tabelle1!$B60 -> 8031765 | H14: =Tabelle1!$B68 -> 8010843 | I14: =Tabelle1!$B76 -> 8034045 | J14: =Tabelle1!$B84 -> 8032335 | K14: =Tabelle1!$B92 -> 8034009 | L14: =Tabelle1!$B100 -> 8032527 | M14: =Tabelle1!$B108 -> 1012521
A15: E | B15: =Tabelle1!B21 -> 8034059 | C15: =Tabelle1!$B29 -> 8023299 | D15: =Tabelle1!$B37 -> 8023320 | E15: =Tabelle1!$B45 -> 8034031 | F15: =Tabelle1!$B53 -> 1046718 | G15: =Tabelle1!$B61 -> 8032583 | H15: =Tabelle1!$B69 -> 8013681 | I15: =Tabelle1!$B77 -> 8034044 | J15: =Tabelle1!$B85 -> 8032294 | K15: =Tabelle1!$B93 -> 8034000 | L15: =Tabelle1!$B101 -> 8032541 | M15: =Tabelle1!$B109 -> 8023348
A16: F | B16: =Tabelle1!B22 -> 8012421 | C16: =Tabelle1!$B30 -> 8034017 | D16: =Tabelle1!$B38 -> 8034030 | E16: =Tabelle1!$B46 -> 8034036 | F16: =Tabelle1!$B54 -> 1046728 | G16: =Tabelle1!$B62 -> 8031512 | H16: =Tabelle1!$B70 -> 8034014 | I16: =Tabelle1!$B78 -> 8034039 | J16: =Tabelle1!$B86 -> 8032319 | K16: =Tabelle1!$B94 -> 8034004 | L16: =Tabelle1!$B102 -> 8021934 | M16: =Tabelle1!$B110 -> 3D7_1K
A17: G | B17: =Tabelle1!B23 -> 8032055 | C17: =Tabelle1!$B31 -> 8013498 | D17: =Tabelle1!$B39 -> 8019456 | E17: =Tabelle1!$B47 -> 5053742 | F17: =Tabelle1!$B55 -> 1046677 | G17: =Tabelle1!$B63 -> 8013676 | H17: =Tabelle1!$B71 -> 8034015 | I17: =Tabelle1!$B79 -> 8034042 | J17: =Tabelle1!$B87 -> 8032348 | K17: =Tabelle1!$B95 -> 8034007 | L17: =Tabelle1!$B103 -> 8021932 | M17: =Tabelle1!$B111 -> Dd2_1K
A18: H | B18: =Tabelle1!B24 -> 5053837 | C18: =Tabelle1!$B32 -> 1012426 | D18: =Tabelle1!$B40 -> 8031773 | E18: =Tabelle1!$B48 -> 8031271 | F18: =Tabelle1!$B56 -> 8034026 | G18: =Tabelle1!$B64 -> 8033342 | H18: =Tabelle1!$B72 -> 8031811 | I18: =Tabelle1!$B80 -> 8034040 | J18: =Tabelle1!$B88 -> 8032265 | K18: =Tabelle1!$B96 -> 8034008 | L18: =Tabelle1!$B104 -> 8023334 | M18: =Tabelle1!$B112 -> NTC
A21: Sample Plate Overview | F21: Plate 2
B23: 1 | C23: 2 | D23: 3 | E23: 4 | F23: 5 | G23: 6 | H23: 7 | I23: 8 | J23: 9 | K23: 10 | L23: 11 | M23: 12
A24: A | B24: =Tabelle1!B115 -> 0 | C24: =Tabelle1!B123 -> 0 | D24: =Tabelle1!B131 -> 0 | E24: =Tabelle1!B139 -> 0 | F24: =Tabelle1!B147 -> 0 | G24: =Tabelle1!B155 -> 0 | H24: =Tabelle1!B163 -> 0 | I24: =Tabelle1!B171 -> 0 | J24: =Tabelle1!B179 -> 0 | K24: =Tabelle1!B187 -> 0 | L24: =Tabelle1!B195 -> 0 | M24: =Tabelle1!B203 -> 0
A25: B | B25: =Tabelle1!B116 -> 0 | C25: =Tabelle1!B124 -> 0 | D25: =Tabelle1!B132 -> 0 | E25: =Tabelle1!B140 -> 0 | F25: =Tabelle1!B148 -> 0 | G25: =Tabelle1!B156 -> 0 | H25: =Tabelle1!B164 -> 0 | I25: =Tabelle1!B172 -> 0 | J25: =Tabelle1!B180 -> 0 | K25: =Tabelle1!B188 -> 0 | L25: =Tabelle1!B196 -> 0 | M25: =Tabelle1!B204 -> 0
A26: C | B26: =Tabelle1!B117 -> 0 | C26: =Tabelle1!B125 -> 0 | D26: =Tabelle1!B133 -> 0 | E26: =Tabelle1!B141 -> 0 | F26: =Tabelle1!B149 -> 0 | G26: =Tabelle1!B157 -> 0 | H26: =Tabelle1!B165 -> 0 | I26: =Tabelle1!B173 -> 0 | J26: =Tabelle1!B181 -> 0 | K26: =Tabelle1!B189 -> 0 | L26: =Tabelle1!B197 -> 0 | M26: =Tabelle1!B205 -> 0
A27: D | B27: =Tabelle1!B118 -> 0 | C27: =Tabelle1!B126 -> 0 | D27: =Tabelle1!B134 -> 0 | E27: =Tabelle1!B142 -> 0 | F27: =Tabelle1!B150 -> 0 | G27: =Tabelle1!B158 -> 0 | H27: =Tabelle1!B166 -> 0 | I27: =Tabelle1!B174 -> 0 | J27: =Tabelle1!B182 -> 0 | K27: =Tabelle1!B190 -> 0 | L27: =Tabelle1!B198 -> 0 | M27: =Tabelle1!B206 -> 0
A28: E | B28: =Tabelle1!B119 -> 0 | C28: =Tabelle1!B127 -> 0 | D28: =Tabelle1!B135 -> 0 | E28: =Tabelle1!B143 -> 0 | F28: =Tabelle1!B151 -> 0 | G28: =Tabelle1!B159 -> 0 | H28: =Tabelle1!B167 -> 0 | I28: =Tabelle1!B175 -> 0 | J28: =Tabelle1!B183 -> 0 | K28: =Tabelle1!B191 -> 0 | L28: =Tabelle1!B199 -> 0 | M28: =Tabelle1!B207 -> 0
A29: F | B29: =Tabelle1!B120 -> 0 | C29: =Tabelle1!B128 -> 0 | D29: =Tabelle1!B136 -> 0 | E29: =Tabelle1!B144 -> 0 | F29: =Tabelle1!B152 -> 0 | G29: =Tabelle1!B160 -> 0 | H29: =Tabelle1!B168 -> 0 | I29: =Tabelle1!B176 -> 0 | J29: =Tabelle1!B184 -> 0 | K29: =Tabelle1!B192 -> 0 | L29: =Tabelle1!B200 -> 0 | M29: =Tabelle1!B208 -> 0
A30: G | B30: =Tabelle1!B121 -> 0 | C30: =Tabelle1!B129 -> 0 | D30: =Tabelle1!B137 -> 0 | E30: =Tabelle1!B145 -> 0 | F30: =Tabelle1!B153 -> 0 | G30: =Tabelle1!B161 -> 0 | H30: =Tabelle1!B169 -> 0 | I30: =Tabelle1!B177 -> 0 | J30: =Tabelle1!B185 -> 0 | K30: =Tabelle1!B193 -> 0 | L30: =Tabelle1!B201 -> 0 | M30: =Tabelle1!B209 -> 0
A31: H | B31: =Tabelle1!B122 -> 0 | C31: =Tabelle1!B130 -> 0 | D31: =Tabelle1!B138 -> 0 | E31: =Tabelle1!B146 -> 0 | F31: =Tabelle1!B154 -> 0 | G31: =Tabelle1!B162 -> 0 | H31: =Tabelle1!B170 -> 0 | I31: =Tabelle1!B178 -> 0 | J31: =Tabelle1!B186 -> 0 | K31: =Tabelle1!B194 -> 0 | L31: =Tabelle1!B202 -> 0 | M31: =Tabelle1!B210 -> 0
A34: Sample Plate Overview | F34: Plate 3
B36: 1 | C36: 2 | D36: 3 | E36: 4 | F36: 5 | G36: 6 | H36: 7 | I36: 8 | J36: 9 | K36: 10 | L36: 11 | M36: 12
A37: A | B37: =Tabelle1!$B213 -> 0 | C37: =Tabelle1!$B221 -> 0 | D37: =Tabelle1!$B2229 -> 0 | E37: =Tabelle1!$B237 -> 0 | F37: =Tabelle1!$B245 -> 0 | G37: =Tabelle1!$B253 -> 0 | H37: =Tabelle1!$B261 -> 0 | I37: =Tabelle1!$B269 -> 0 | J37: =Tabelle1!$B277 -> 0 | K37: =Tabelle1!$B285 -> 0 | L37: =Tabelle1!$B293 -> 0 | M37: =Tabelle1!$B301 -> 0
A38: B | B38: =Tabelle1!$B214 -> 0 | C38: =Tabelle1!$B222 -> 0 | D38: =Tabelle1!$B2230 -> 0 | E38: =Tabelle1!$B238 -> 0 | F38: =Tabelle1!$B246 -> 0 | G38: =Tabelle1!$B254 -> 0 | H38: =Tabelle1!$B262 -> 0 | I38: =Tabelle1!$B270 -> 0 | J38: =Tabelle1!$B278 -> 0 | K38: =Tabelle1!$B286 -> 0 | L38: =Tabelle1!$B294 -> 0 | M38: =Tabelle1!$B302 -> 0
A39: C | B39: =Tabelle1!$B215 -> 0 | C39: =Tabelle1!$B223 -> 0 | D39: =Tabelle1!$B2231 -> 0 | E39: =Tabelle1!$B239 -> 0 | F39: =Tabelle1!$B247 -> 0 | G39: =Tabelle1!$B255 -> 0 | H39: =Tabelle1!$B263 -> 0 | I39: =Tabelle1!$B271 -> 0 | J39: =Tabelle1!$B279 -> 0 | K39: =Tabelle1!$B287 -> 0 | L39: =Tabelle1!$B295 -> 0 | M39: =Tabelle1!$B303 -> 0
A40: D | B40: =Tabelle1!$B216 -> 0 | C40: =Tabelle1!$B224 -> 0 | D40: =Tabelle1!$B2232 -> 0 | E40: =Tabelle1!$B240 -> 0 | F40: =Tabelle1!$B248 -> 0 | G40: =Tabelle1!$B256 -> 0 | H40: =Tabelle1!$B264 -> 0 | I40: =Tabelle1!$B272 -> 0 | J40: =Tabelle1!$B280 -> 0 | K40: =Tabelle1!$B288 -> 0 | L40: =Tabelle1!$B296 -> 0 | M40: =Tabelle1!$B304 -> 0
A41: E | B41: =Tabelle1!$B217 -> 0 | C41: =Tabelle1!$B225 -> 0 | D41: =Tabelle1!$B2233 -> 0 | E41: =Tabelle1!$B241 -> 0 | F41: =Tabelle1!$B249 -> 0 | G41: =Tabelle1!$B257 -> 0 | H41: =Tabelle1!$B265 -> 0 | I41: =Tabelle1!$B273 -> 0 | J41: =Tabelle1!$B281 -> 0 | K41: =Tabelle1!$B289 -> 0 | L41: =Tabelle1!$B297 -> 0 | M41: =Tabelle1!$B305 -> 0
A42: F | B42: =Tabelle1!$B218 -> 0 | C42: =Tabelle1!$B226 -> 0 | D42: =Tabelle1!$B2234 -> 0 | E42: =Tabelle1!$B242 -> 0 | F42: =Tabelle1!$B250 -> 0 | G42: =Tabelle1!$B258 -> 0 | H42: =Tabelle1!$B266 -> 0 | I42: =Tabelle1!$B274 -> 0 | J42: =Tabelle1!$B282 -> 0 | K42: =Tabelle1!$B290 -> 0 | L42: =Tabelle1!$B298 -> 0 | M42: =Tabelle1!$B306 -> 0
A43: G | B43: =Tabelle1!$B219 -> 0 | C43: =Tabelle1!$B227 -> 0 | D43: =Tabelle1!$B2235 -> 0 | E43: =Tabelle1!$B243 -> 0 | F43: =Tabelle1!$B251 -> 0 | G43: =Tabelle1!$B259 -> 0 | H43: =Tabelle1!$B267 -> 0 | I43: =Tabelle1!$B275 -> 0 | J43: =Tabelle1!$B283 -> 0 | K43: =Tabelle1!$B291 -> 0 | L43: =Tabelle1!$B299 -> 0 | M43: =Tabelle1!$B307 -> 0
A44: H | B44: =Tabelle1!$B220 -> 0 | C44: =Tabelle1!$B228 -> 0 | D44: =Tabelle1!$B2236 -> 0 | E44: =Tabelle1!$B244 -> 0 | F44: =Tabelle1!$B252 -> 0 | G44: =Tabelle1!$B260 -> 0 | H44: =Tabelle1!$B268 -> 0 | I44: =Tabelle1!$B276 -> 0 | J44: =Tabelle1!$B284 -> 0 | K44: =Tabelle1!$B292 -> 0 | L44: =Tabelle1!$B300 -> 0 | M44: =Tabelle1!$B308 -> 0
A47: Sample Plate Overview | F47: Plate 4
B49: 1 | C49: 2 | D49: 3 | E49: 4 | F49: 5 | G49: 6 | H49: 7 | I49: 8 | J49: 9 | K49: 10 | L49: 11 | M49: 12
A50: A | B50: =Tabelle1!$B311 -> 0 | C50: =Tabelle1!$B319 -> 0 | D50: =Tabelle1!$B327 -> 0 | E50: =Tabelle1!$B335 -> 0 | F50: =Tabelle1!$B343 -> 0 | G50: =Tabelle1!$B351 -> 0 | H50: =Tabelle1!$B359 -> 0 | I50: =Tabelle1!$B367 -> 0 | J50: =Tabelle1!$B375 -> 0 | K50: =Tabelle1!$B383 -> 0 | L50: =Tabelle1!$B391 -> 0 | M50: =Tabelle1!$B399 -> 0
A51: B | B51: =Tabelle1!$B312 -> 0 | C51: =Tabelle1!$B320 -> 0 | D51: =Tabelle1!$B328 -> 0 | E51: =Tabelle1!$B336 -> 0 | F51: =Tabelle1!$B344 -> 0 | G51: =Tabelle1!$B352 -> 0 | H51: =Tabelle1!$B360 -> 0 | I51: =Tabelle1!$B368 -> 0 | J51: =Tabelle1!$B376 -> 0 | K51: =Tabelle1!$B384 -> 0 | L51: =Tabelle1!$B392 -> 0 | M51: =Tabelle1!$B400 -> 0
A52: C | B52: =Tabelle1!$B313 -> 0 | C52: =Tabelle1!$B321 -> 0 | D52: =Tabelle1!$B329 -> 0 | E52: =Tabelle1!$B337 -> 0 | F52: =Tabelle1!$B345 -> 0 | G52: =Tabelle1!$B353 -> 0 | H52: =Tabelle1!$B361 -> 0 | I52: =Tabelle1!$B369 -> 0 | J52: =Tabelle1!$B377 -> 0 | K52: =Tabelle1!$B385 -> 0 | L52: =Tabelle1!$B393 -> 0 | M52: =Tabelle1!$B401 -> 0
A53: D | B53: =Tabelle1!$B314 -> 0 | C53: =Tabelle1!$B322 -> 0 | D53: =Tabelle1!$B330 -> 0 | E53: =Tabelle1!$B338 -> 0 | F53: =Tabelle1!$B346 -> 0 | G53: =Tabelle1!$B354 -> 0 | H53: =Tabelle1!$B362 -> 0 | I53: =Tabelle1!$B370 -> 0 | J53: =Tabelle1!$B378 -> 0 | K53: =Tabelle1!$B386 -> 0 | L53: =Tabelle1!$B394 -> 0 | M53: =Tabelle1!$B402 -> 0
A54: E | B54: =Tabelle1!$B315 -> 0 | C54: =Tabelle1!$B323 -> 0 | D54: =Tabelle1!$B331 -> 0 | E54: =Tabelle1!$B339 -> 0 | F54: =Tabelle1!$B347 -> 0 | G54: =Tabelle1!$B355 -> 0 | H54: =Tabelle1!$B363 -> 0 | I54: =Tabelle1!$B371 -> 0 | J54: =Tabelle1!$B379 -> 0 | K54: =Tabelle1!$B387 -> 0 | L54: =Tabelle1!$B395 -> 0 | M54: =Tabelle1!$B403 -> 0
A55: F | B55: =Tabelle1!$B316 -> 0 | C55: =Tabelle1!$B324 -> 0 | D55: =Tabelle1!$B332 -> 0 | E55: =Tabelle1!$B340 -> 0 | F55: =Tabelle1!$B348 -> 0 | G55: =Tabelle1!$B356 -> 0 | H55: =Tabelle1!$B364 -> 0 | I55: =Tabelle1!$B372 -> 0 | J55: =Tabelle1!$B380 -> 0 | K55: =Tabelle1!$B388 -> 0 | L55: =Tabelle1!$B396 -> 0 | M55: =Tabelle1!$B404 -> 0
...
